<?xml version='1.0' encoding='utf-8'?>
<robot name="robot">
  <link name="link_x8_1_pcb_x8_1">
    <visual>
      <origin xyz="0 0 0" rpy="0 0 0" />
      <geometry>
        <mesh filename="./meshes/x8_1_pcb_x8_1.stl" />
      </geometry>
      <material name="link_x8_1_pcb_x8_1_material">
        <color rgba="0.76862745 0.88627451 0.95294118 1" />
      </material>
    </visual>
    <collision>
      <origin xyz="0 0 0" rpy="0 0 0" />
      <geometry>
        <mesh filename="./meshes/x8_1_pcb_x8_1.stl" />
      </geometry>
    </collision>
    <inertial>
      <mass value="0.048559947" />
      <inertia ixx="1.3682683e-05" iyy="1.6841341e-05" izz="2.9259442e-05" ixy="0" ixz="0" iyz="0" />
      <origin xyz="0 0 0" rpy="0 0 0" />
    </inertial>
  </link>
  <link name="link_x8_1_outer_x8_1">
    <visual>
      <origin xyz="0 0 0" rpy="0 0 0" />
      <geometry>
        <mesh filename="./meshes/x8_1_outer_x8_1.stl" />
      </geometry>
      <material name="link_x8_1_outer_x8_1_material">
        <color rgba="0.91764706 0.91764706 0.91764706 1" />
      </material>
    </visual>
    <collision>
      <origin xyz="0 0 0" rpy="0 0 0" />
      <geometry>
        <mesh filename="./meshes/x8_1_outer_x8_1.stl" />
      </geometry>
    </collision>
    <inertial>
      <mass value="0.64135588" />
      <inertia ixx="0.0004995997" iyy="0.00049960271" izz="0.00089477222" ixy="0" ixz="0" iyz="0" />
      <origin xyz="0 0 0.015652571" rpy="3.5012681e-06 0 0" />
    </inertial>
  </link>
  <joint name="joint_x8_1_fastened_1" type="fixed">
    <origin xyz="0 0.0021459929 -0.00625" rpy="3.1415927 0 0" />
    <parent link="link_x8_1_pcb_x8_1" />
    <child link="link_x8_1_outer_x8_1" />
  </joint>
  <link name="link_x8_1_inner_x8_1">
    <visual>
      <origin xyz="0 0 0" rpy="0 0 0" />
      <geometry>
        <mesh filename="./meshes/x8_1_inner_x8_1.stl" />
      </geometry>
      <material name="link_x8_1_inner_x8_1_material">
        <color rgba="0.97254902 0.52941176 0.0039215686 1" />
      </material>
    </visual>
    <collision>
      <origin xyz="0 0 0" rpy="0 0 0" />
      <geometry>
        <mesh filename="./meshes/x8_1_inner_x8_1.stl" />
      </geometry>
    </collision>
    <inertial>
      <mass value="0.13865861" />
      <inertia ixx="2.7062809e-05" iyy="2.7062809e-05" izz="2.8959079e-05" ixy="0" ixz="0" iyz="0" />
      <origin xyz="0 0 -0.0165" rpy="3.1415927 0 0" />
    </inertial>
  </link>
  <joint name="joint_x8_1_dof_x8" type="revolute">
    <origin xyz="0 0 0" rpy="3.1415927 0 0" />
    <parent link="link_x8_1_outer_x8_1" />
    <child link="link_x8_1_inner_x8_1" />
    <limit effort="80" velocity="5" lower="-2.0943951" upper="2.0943951" />
    <axis xyz="0 0 -1" />
  </joint>
  <link name="link_shoulder_inner_1">
    <visual>
      <origin xyz="0 0 0" rpy="0 0 0" />
      <geometry>
        <mesh filename="./meshes/shoulder_inner_1.stl" />
      </geometry>
      <material name="link_shoulder_inner_1_material">
        <color rgba="0.91764706 0.91764706 0.91764706 1" />
      </material>
    </visual>
    <collision>
      <origin xyz="0 0 0" rpy="0 0 0" />
      <geometry>
        <mesh filename="./meshes/shoulder_inner_1.stl" />
      </geometry>
    </collision>
    <inertial>
      <mass value="0.098694821" />
      <inertia ixx="0.00029234831" iyy="0.00037180534" izz="0.0001651911" ixy="0" ixz="1.5856387e-06" iyz="-3.1309639e-05" />
      <origin xyz="0.00053435842 0.030503746 0.051654382" rpy="1.7179432 -0.0013420304 -1.5828294" />
    </inertial>
  </link>
  <joint name="joint_fastened_8" type="fixed">
    <origin xyz="0 0.0155 -0.033" rpy="3.1415927 0 0" />
    <parent link="link_x8_1_inner_x8_1" />
    <child link="link_shoulder_inner_1" />
  </joint>
  <link name="link_x8_2_outer_x8_1">
    <visual>
      <origin xyz="0 0 0" rpy="0 0 0" />
      <geometry>
        <mesh filename="./meshes/x8_2_outer_x8_1.stl" />
      </geometry>
      <material name="link_x8_2_outer_x8_1_material">
        <color rgba="0.91764706 0.91764706 0.91764706 1" />
      </material>
    </visual>
    <collision>
      <origin xyz="0 0 0" rpy="0 0 0" />
      <geometry>
        <mesh filename="./meshes/x8_2_outer_x8_1.stl" />
      </geometry>
    </collision>
    <inertial>
      <mass value="0.64135588" />
      <inertia ixx="0.0004995997" iyy="0.00049960271" izz="0.00089477222" ixy="0" ixz="0" iyz="0" />
      <origin xyz="0.033978714 -0.024687118 -0.015652571" rpy="-3.1415892 0 0" />
    </inertial>
  </link>
  <joint name="joint_fastened_11" type="fixed">
    <origin xyz="-0.033978714 0.0485 0.052313019" rpy="-1.5707963 0 0" />
    <parent link="link_shoulder_inner_1" />
    <child link="link_x8_2_outer_x8_1" />
  </joint>
  <link name="link_x8_2_inner_x8_1">
    <visual>
      <origin xyz="0 0 0" rpy="0 0 0" />
      <geometry>
        <mesh filename="./meshes/x8_2_inner_x8_1.stl" />
      </geometry>
      <material name="link_x8_2_inner_x8_1_material">
        <color rgba="0.97254902 0.52941176 0.0039215686 1" />
      </material>
    </visual>
    <collision>
      <origin xyz="0 0 0" rpy="0 0 0" />
      <geometry>
        <mesh filename="./meshes/x8_2_inner_x8_1.stl" />
      </geometry>
    </collision>
    <inertial>
      <mass value="0.13865861" />
      <inertia ixx="2.7062809e-05" iyy="2.7062809e-05" izz="2.8959079e-05" ixy="0" ixz="0" iyz="0" />
      <origin xyz="0 0 -0.0165" rpy="3.1415927 0 0" />
    </inertial>
  </link>
  <joint name="joint_x8_2_dof_x8" type="revolute">
    <origin xyz="0.033978714 -0.024686981 0" rpy="0 0 0" />
    <parent link="link_x8_2_outer_x8_1" />
    <child link="link_x8_2_inner_x8_1" />
    <limit effort="80" velocity="5" lower="0" upper="1.9198622" />
    <axis xyz="0 0 -1" />
  </joint>
  <link name="link_x8_2_pcb_x8_1">
    <visual>
      <origin xyz="0 0 0" rpy="0 0 0" />
      <geometry>
        <mesh filename="./meshes/x8_2_pcb_x8_1.stl" />
      </geometry>
      <material name="link_x8_2_pcb_x8_1_material">
        <color rgba="0.76862745 0.88627451 0.95294118 1" />
      </material>
    </visual>
    <collision>
      <origin xyz="0 0 0" rpy="0 0 0" />
      <geometry>
        <mesh filename="./meshes/x8_2_pcb_x8_1.stl" />
      </geometry>
    </collision>
    <inertial>
      <mass value="0.048559947" />
      <inertia ixx="1.3682683e-05" iyy="1.6841341e-05" izz="2.9259442e-05" ixy="0" ixz="0" iyz="0" />
      <origin xyz="0 0.0021459929 -0.00625" rpy="3.1415927 0 0" />
    </inertial>
  </link>
  <joint name="joint_x8_2_fastened_1" type="fixed">
    <origin xyz="0.033978714 -0.024686981 0" rpy="3.1415927 0 0" />
    <parent link="link_x8_2_outer_x8_1" />
    <child link="link_x8_2_pcb_x8_1" />
  </joint>
  <link name="link_shoulder_nontorso_1">
    <visual>
      <origin xyz="0 0 0" rpy="0 0 0" />
      <geometry>
        <mesh filename="./meshes/shoulder_nontorso_1.stl" />
      </geometry>
      <material name="link_shoulder_nontorso_1_material">
        <color rgba="0.91764706 0.91764706 0.91764706 1" />
      </material>
    </visual>
    <collision>
      <origin xyz="0 0 0" rpy="0 0 0" />
      <geometry>
        <mesh filename="./meshes/shoulder_nontorso_1.stl" />
      </geometry>
    </collision>
    <inertial>
      <mass value="0.063774449" />
      <inertia ixx="0.00010527094" iyy="0.00014035757" izz="8.752817e-05" ixy="0" ixz="0" iyz="2.014856e-05" />
      <origin xyz="0 -0.00039671854 -0.036390201" rpy="1.2449817 2.5435401e-06 -1.5707837" />
    </inertial>
  </link>
  <joint name="joint_fastened_1" type="fixed">
    <origin xyz="0 0.0155 -0.033" rpy="0 0 0" />
    <parent link="link_x8_2_inner_x8_1" />
    <child link="link_shoulder_nontorso_1" />
  </joint>
  <link name="link_x6_1_outer_x6_1">
    <visual>
      <origin xyz="0 0 0" rpy="0 0 0" />
      <geometry>
        <mesh filename="./meshes/x6_1_outer_x6_1.stl" />
      </geometry>
      <material name="link_x6_1_outer_x6_1_material">
        <color rgba="0.97254902 0.52941176 0.0039215686 1" />
      </material>
    </visual>
    <collision>
      <origin xyz="0 0 0" rpy="0 0 0" />
      <geometry>
        <mesh filename="./meshes/x6_1_outer_x6_1.stl" />
      </geometry>
    </collision>
    <inertial>
      <mass value="0.29628126" />
      <inertia ixx="0.00015648456" iyy="0.00026587276" izz="0.00015648465" ixy="0" ixz="0" iyz="0" />
      <origin xyz="0 0.036 -0.015437886" rpy="-3.1415663 0 -1.5707967" />
    </inertial>
  </link>
  <joint name="joint_fastened_2" type="fixed">
    <origin xyz="-0.036 0.017 -0.0705" rpy="-1.5707963 -1.5707963 0" />
    <parent link="link_shoulder_nontorso_1" />
    <child link="link_x6_1_outer_x6_1" />
  </joint>
  <link name="link_x6_1_inner_x6_1">
    <visual>
      <origin xyz="0 0 0" rpy="0 0 0" />
      <geometry>
        <mesh filename="./meshes/x6_1_inner_x6_1.stl" />
      </geometry>
      <material name="link_x6_1_inner_x6_1_material">
        <color rgba="0.49803922 0.49803922 0.49803922 1" />
      </material>
    </visual>
    <collision>
      <origin xyz="0 0 0" rpy="0 0 0" />
      <geometry>
        <mesh filename="./meshes/x6_1_inner_x6_1.stl" />
      </geometry>
    </collision>
    <inertial>
      <mass value="0.053731806" />
      <inertia ixx="7.930353e-06" iyy="6.4016694e-06" izz="7.930353e-06" ixy="0" ixz="0" iyz="0" />
      <origin xyz="0 0 -0.01625" rpy="1.5707963 1.5707963 0" />
    </inertial>
  </link>
  <joint name="joint_x6_1_dof_x6" type="revolute">
    <origin xyz="0 0.036 0" rpy="0 0 0" />
    <parent link="link_x6_1_outer_x6_1" />
    <child link="link_x6_1_inner_x6_1" />
    <limit effort="80" velocity="5" lower="-1.0471976" upper="3.6651914" />
    <axis xyz="0 0 -1" />
  </joint>
  <link name="link_x6_1_pcb_x6_1">
    <visual>
      <origin xyz="0 0 0" rpy="0 0 0" />
      <geometry>
        <mesh filename="./meshes/x6_1_pcb_x6_1.stl" />
      </geometry>
      <material name="link_x6_1_pcb_x6_1_material">
        <color rgba="0.98039216 0.71372549 0.0039215686 1" />
      </material>
    </visual>
    <collision>
      <origin xyz="0 0 0" rpy="0 0 0" />
      <geometry>
        <mesh filename="./meshes/x6_1_pcb_x6_1.stl" />
      </geometry>
    </collision>
    <inertial>
      <mass value="0.032395494" />
      <inertia ixx="6.266658e-06" iyy="1.3729044e-05" izz="8.2398782e-06" ixy="0" ixz="0" iyz="0" />
      <origin xyz="-0.0024625066 8.0472631e-06 -0.006" rpy="0.003369609 0.003369609 3.1415927" />
    </inertial>
  </link>
  <joint name="joint_x6_1_fastened_1" type="fixed">
    <origin xyz="0 0.036 0" rpy="3.1415927 0 0" />
    <parent link="link_x6_1_outer_x6_1" />
    <child link="link_x6_1_pcb_x6_1" />
  </joint>
  <link name="link_elbow_1">
    <visual>
      <origin xyz="0 0 0" rpy="0 0 0" />
      <geometry>
        <mesh filename="./meshes/elbow_1.stl" />
      </geometry>
      <material name="link_elbow_1_material">
        <color rgba="0.97254902 0.52941176 0.0039215686 1" />
      </material>
    </visual>
    <collision>
      <origin xyz="0 0 0" rpy="0 0 0" />
      <geometry>
        <mesh filename="./meshes/elbow_1.stl" />
      </geometry>
    </collision>
    <inertial>
      <mass value="0.098238471" />
      <inertia ixx="0.00045271693" iyy="8.9162813e-05" izz="0.00050860798" ixy="0" ixz="0" iyz="1.2964992e-05" />
      <origin xyz="0.035397182 -6.3197008e-05 -0.095352686" rpy="1.6213128 -1.5398856 1.5169082" />
    </inertial>
  </link>
  <joint name="joint_fastened_3" type="fixed">
    <origin xyz="0.00575 0.0099592921 -0.0325" rpy="0 0 -2.0943951" />
    <parent link="link_x6_1_inner_x6_1" />
    <child link="link_elbow_1" />
  </joint>
  <link name="link_x6_2_outer_x6_1">
    <visual>
      <origin xyz="0 0 0" rpy="0 0 0" />
      <geometry>
        <mesh filename="./meshes/x6_2_outer_x6_1.stl" />
      </geometry>
      <material name="link_x6_2_outer_x6_1_material">
        <color rgba="0.97254902 0.52941176 0.0039215686 1" />
      </material>
    </visual>
    <collision>
      <origin xyz="0 0 0" rpy="0 0 0" />
      <geometry>
        <mesh filename="./meshes/x6_2_outer_x6_1.stl" />
      </geometry>
    </collision>
    <inertial>
      <mass value="0.29628126" />
      <inertia ixx="0.00015648456" iyy="0.00026587276" izz="0.00015648465" ixy="0" ixz="0" iyz="0" />
      <origin xyz="-0.031176923 0.018 -0.015437886" rpy="-3.1415663 0 -1.5707967" />
    </inertial>
  </link>
  <joint name="joint_fastened_4" type="fixed">
    <origin xyz="0.044 0.018 -0.15032309" rpy="-3.1415927 -1.5707963 0" />
    <parent link="link_elbow_1" />
    <child link="link_x6_2_outer_x6_1" />
  </joint>
  <link name="link_elbow_case_1">
    <visual>
      <origin xyz="0 0 0" rpy="0 0 0" />
      <geometry>
        <mesh filename="./meshes/elbow_case_1.stl" />
      </geometry>
      <material name="link_elbow_case_1_material">
        <color rgba="0.64705882 0.64705882 0.64705882 1" />
      </material>
    </visual>
    <collision>
      <origin xyz="0 0 0" rpy="0 0 0" />
      <geometry>
        <mesh filename="./meshes/elbow_case_1.stl" />
      </geometry>
    </collision>
    <inertial>
      <mass value="0.074847468" />
      <inertia ixx="6.1192099e-05" iyy="0.00026901522" izz="0.00032097721" ixy="-2.3127639e-06" ixz="-1.5578374e-05" iyz="0" />
      <origin xyz="-0.013470014 -0.03920712 -0.017022247" rpy="3.134696 -0.011643395 3.0819768" />
    </inertial>
  </link>
  <joint name="joint_fastened_9" type="fixed">
    <origin xyz="0.014 0.04032563 -0.10877135" rpy="0 1.5707963 0" />
    <parent link="link_elbow_1" />
    <child link="link_elbow_case_1" />
  </joint>
  <link name="link_x6_2_inner_x6_1">
    <visual>
      <origin xyz="0 0 0" rpy="0 0 0" />
      <geometry>
        <mesh filename="./meshes/x6_2_inner_x6_1.stl" />
      </geometry>
      <material name="link_x6_2_inner_x6_1_material">
        <color rgba="0.49803922 0.49803922 0.49803922 1" />
      </material>
    </visual>
    <collision>
      <origin xyz="0 0 0" rpy="0 0 0" />
      <geometry>
        <mesh filename="./meshes/x6_2_inner_x6_1.stl" />
      </geometry>
    </collision>
    <inertial>
      <mass value="0.053731806" />
      <inertia ixx="7.930353e-06" iyy="6.4016694e-06" izz="7.930353e-06" ixy="0" ixz="0" iyz="0" />
      <origin xyz="0 0 -0.01625" rpy="1.5707963 1.5707963 0" />
    </inertial>
  </link>
  <joint name="joint_x6_2_dof_x6" type="revolute">
    <origin xyz="-0.031176915 0.018 0" rpy="0 0 0" />
    <parent link="link_x6_2_outer_x6_1" />
    <child link="link_x6_2_inner_x6_1" />
    <limit effort="80" velocity="5" lower="-1.5707963" upper="1.5707963" />
    <axis xyz="0 0 -1" />
  </joint>
  <link name="link_x6_2_pcb_x6_1">
    <visual>
      <origin xyz="0 0 0" rpy="0 0 0" />
      <geometry>
        <mesh filename="./meshes/x6_2_pcb_x6_1.stl" />
      </geometry>
      <material name="link_x6_2_pcb_x6_1_material">
        <color rgba="0.98039216 0.71372549 0.0039215686 1" />
      </material>
    </visual>
    <collision>
      <origin xyz="0 0 0" rpy="0 0 0" />
      <geometry>
        <mesh filename="./meshes/x6_2_pcb_x6_1.stl" />
      </geometry>
    </collision>
    <inertial>
      <mass value="0.032395494" />
      <inertia ixx="6.266658e-06" iyy="1.3729044e-05" izz="8.2398782e-06" ixy="0" ixz="0" iyz="0" />
      <origin xyz="-0.0024625066 8.0472631e-06 -0.006" rpy="0.003369609 0.003369609 3.1415927" />
    </inertial>
  </link>
  <joint name="joint_x6_2_fastened_1" type="fixed">
    <origin xyz="-0.031176915 0.018 0" rpy="3.1415927 0 0" />
    <parent link="link_x6_2_outer_x6_1" />
    <child link="link_x6_2_pcb_x6_1" />
  </joint>
  <link name="link_forearm_1">
    <visual>
      <origin xyz="0 0 0" rpy="0 0 0" />
      <geometry>
        <mesh filename="./meshes/forearm_1.stl" />
      </geometry>
      <material name="link_forearm_1_material">
        <color rgba="0.97254902 0.52941176 0.0039215686 1" />
      </material>
    </visual>
    <collision>
      <origin xyz="0 0 0" rpy="0 0 0" />
      <geometry>
        <mesh filename="./meshes/forearm_1.stl" />
      </geometry>
    </collision>
    <inertial>
      <mass value="0.06383574" />
      <inertia ixx="0.00010660821" iyy="0.00012183306" izz="4.9046771e-05" ixy="0" ixz="0" iyz="4.8948211e-06" />
      <origin xyz="-0.067423421 0 0.0020181814" rpy="-0.78424283 1.4762905 -2.3572805" />
    </inertial>
  </link>
  <joint name="joint_fastened_5" type="fixed">
    <origin xyz="0.0115 0 -0.0325" rpy="3.1415927 0 0" />
    <parent link="link_x6_2_inner_x6_1" />
    <child link="link_forearm_1" />
  </joint>
  <link name="link_x4_1_pcb_x4_h_1">
    <visual>
      <origin xyz="0 0 0" rpy="0 0 0" />
      <geometry>
        <mesh filename="./meshes/x4_1_pcb_x4_h_1.stl" />
      </geometry>
      <material name="link_x4_1_pcb_x4_h_1_material">
        <color rgba="0.97254902 0.52941176 0.0039215686 1" />
      </material>
    </visual>
    <collision>
      <origin xyz="0 0 0" rpy="0 0 0" />
      <geometry>
        <mesh filename="./meshes/x4_1_pcb_x4_h_1.stl" />
      </geometry>
    </collision>
    <inertial>
      <mass value="0.029564618" />
      <inertia ixx="4.8930802e-06" iyy="6.0010713e-06" izz="9.9964453e-06" ixy="0" ixz="0" iyz="0" />
      <origin xyz="0.015909903 0.014250744 -0.0067605702" rpy="3.1415927 0 0" />
    </inertial>
  </link>
  <joint name="joint_fastened_6" type="fixed">
    <origin xyz="-0.076 -0.015909901 -0.010909904" rpy="1.5707963 0 1.5707963" />
    <parent link="link_forearm_1" />
    <child link="link_x4_1_pcb_x4_h_1" />
  </joint>
  <link name="link_x4_1_outer_x4_h_1">
    <visual>
      <origin xyz="0 0 0" rpy="0 0 0" />
      <geometry>
        <mesh filename="./meshes/x4_1_outer_x4_h_1.stl" />
      </geometry>
      <material name="link_x4_1_outer_x4_h_1_material">
        <color rgba="0.76862745 0.88627451 0.95294118 1" />
      </material>
    </visual>
    <collision>
      <origin xyz="0 0 0" rpy="0 0 0" />
      <geometry>
        <mesh filename="./meshes/x4_1_outer_x4_h_1.stl" />
      </geometry>
    </collision>
    <inertial>
      <mass value="0.15533844" />
      <inertia ixx="5.6668323e-05" iyy="5.6668375e-05" izz="8.3408195e-05" ixy="0" ixz="0" iyz="0" />
      <origin xyz="0 0 0.01700001" rpy="1.3941927e-06 0 0" />
    </inertial>
  </link>
  <joint name="joint_x4_1_fastened_1" type="fixed">
    <origin xyz="0.015909904 0.015909902 -0.0135" rpy="3.1415927 0 0" />
    <parent link="link_x4_1_pcb_x4_h_1" />
    <child link="link_x4_1_outer_x4_h_1" />
  </joint>
  <link name="link_x4_1_inner_x4_h_1">
    <visual>
      <origin xyz="0 0 0" rpy="0 0 0" />
      <geometry>
        <mesh filename="./meshes/x4_1_inner_x4_h_1.stl" />
      </geometry>
      <material name="link_x4_1_inner_x4_h_1_material">
        <color rgba="0.97254902 0.52941176 0.0039215686 1" />
      </material>
    </visual>
    <collision>
      <origin xyz="0 0 0" rpy="0 0 0" />
      <geometry>
        <mesh filename="./meshes/x4_1_inner_x4_h_1.stl" />
      </geometry>
    </collision>
    <inertial>
      <mass value="0.14964637" />
      <inertia ixx="2.7715788e-05" iyy="2.7715788e-05" izz="2.5745478e-05" ixy="0" ixz="0" iyz="0" />
      <origin xyz="0 0 -0.01725" rpy="3.1415927 0 3.1415927" />
    </inertial>
  </link>
  <joint name="joint_x4_1_dof_x4" type="revolute">
    <origin xyz="0 0 0" rpy="3.1415927 0 0" />
    <parent link="link_x4_1_outer_x4_h_1" />
    <child link="link_x4_1_inner_x4_h_1" />
    <limit effort="80" velocity="5" lower="-3.1415927" upper="3.1415927" />
    <axis xyz="0 0 -1" />
  </joint>
  <link name="link_hand_right_1_wrist_pitch_right_2">
    <visual>
      <origin xyz="0 0 0" rpy="0 0 0" />
      <geometry>
        <mesh filename="./meshes/hand_right_1_wrist_pitch_right_2.stl" />
      </geometry>
      <material name="link_hand_right_1_wrist_pitch_right_2_material">
        <color rgba="0.64705882 0.64705882 0.64705882 1" />
      </material>
    </visual>
    <collision>
      <origin xyz="0 0 0" rpy="0 0 0" />
      <geometry>
        <mesh filename="./meshes/hand_right_1_wrist_pitch_right_2.stl" />
      </geometry>
    </collision>
    <inertial>
      <mass value="0.11883921" />
      <inertia ixx="0.00022396918" iyy="0.00030973639" izz="0.00022964024" ixy="-2.3996515e-06" ixz="8.07447e-05" iyz="0" />
      <origin xyz="0.076364792 -0.0069891141 -0.041733842" rpy="0.13573534 -0.38777107 0.5781489" />
    </inertial>
  </link>
  <joint name="joint_fastened_10" type="fixed">
    <origin xyz="-0.0012020773 -0.011437002 -0.0345" rpy="0 0 1.5707963" />
    <parent link="link_x4_1_inner_x4_h_1" />
    <child link="link_hand_right_1_wrist_pitch_right_2" />
  </joint>
  <link name="link_hand_right_1_x4_3_pcb_x4_h_1">
    <visual>
      <origin xyz="0 0 0" rpy="0 0 0" />
      <geometry>
        <mesh filename="./meshes/hand_right_1_x4_3_pcb_x4_h_1.stl" />
      </geometry>
      <material name="link_hand_right_1_x4_3_pcb_x4_h_1_material">
        <color rgba="0.97254902 0.52941176 0.0039215686 1" />
      </material>
    </visual>
    <collision>
      <origin xyz="0 0 0" rpy="0 0 0" />
      <geometry>
        <mesh filename="./meshes/hand_right_1_x4_3_pcb_x4_h_1.stl" />
      </geometry>
    </collision>
    <inertial>
      <mass value="0.029564618" />
      <inertia ixx="4.8930802e-06" iyy="6.0010713e-06" izz="9.9964453e-06" ixy="0" ixz="0" iyz="0" />
      <origin xyz="-0.015909904 -0.017569059 -0.0067605702" rpy="3.1415927 0 0" />
    </inertial>
  </link>
  <joint name="joint_hand_right_1_fastened_5" type="fixed">
    <origin xyz="0.1103037 0.0091503732 -0.062090098" rpy="1.5707963 0 1.5707963" />
    <parent link="link_hand_right_1_wrist_pitch_right_2" />
    <child link="link_hand_right_1_x4_3_pcb_x4_h_1" />
  </joint>
  <link name="link_hand_right_1_x4_3_outer_x4_h_1">
    <visual>
      <origin xyz="0 0 0" rpy="0 0 0" />
      <geometry>
        <mesh filename="./meshes/hand_right_1_x4_3_outer_x4_h_1.stl" />
      </geometry>
      <material name="link_hand_right_1_x4_3_outer_x4_h_1_material">
        <color rgba="0.76862745 0.88627451 0.95294118 1" />
      </material>
    </visual>
    <collision>
      <origin xyz="0 0 0" rpy="0 0 0" />
      <geometry>
        <mesh filename="./meshes/hand_right_1_x4_3_outer_x4_h_1.stl" />
      </geometry>
    </collision>
    <inertial>
      <mass value="0.15533844" />
      <inertia ixx="5.6668323e-05" iyy="5.6668375e-05" izz="8.3408195e-05" ixy="0" ixz="0" iyz="0" />
      <origin xyz="0 0 0.01700001" rpy="1.3941927e-06 0 0" />
    </inertial>
  </link>
  <joint name="joint_hand_right_1_x4_3_fastened_1" type="fixed">
    <origin xyz="-0.015909904 -0.015909902 -0.0135" rpy="3.1415927 0 0" />
    <parent link="link_hand_right_1_x4_3_pcb_x4_h_1" />
    <child link="link_hand_right_1_x4_3_outer_x4_h_1" />
  </joint>
  <link name="link_hand_right_1_x4_3_inner_x4_h_1">
    <visual>
      <origin xyz="0 0 0" rpy="0 0 0" />
      <geometry>
        <mesh filename="./meshes/hand_right_1_x4_3_inner_x4_h_1.stl" />
      </geometry>
      <material name="link_hand_right_1_x4_3_inner_x4_h_1_material">
        <color rgba="0.97254902 0.52941176 0.0039215686 1" />
      </material>
    </visual>
    <collision>
      <origin xyz="0 0 0" rpy="0 0 0" />
      <geometry>
        <mesh filename="./meshes/hand_right_1_x4_3_inner_x4_h_1.stl" />
      </geometry>
    </collision>
    <inertial>
      <mass value="0.14964637" />
      <inertia ixx="2.7715788e-05" iyy="2.7715788e-05" izz="2.5745478e-05" ixy="0" ixz="0" iyz="0" />
      <origin xyz="0 0 -0.01725" rpy="3.1415927 0 3.1415927" />
    </inertial>
  </link>
  <joint name="joint_hand_right_1_x4_3_dof_x4" type="revolute">
    <origin xyz="0 0 0" rpy="3.1415927 0 0" />
    <parent link="link_hand_right_1_x4_3_outer_x4_h_1" />
    <child link="link_hand_right_1_x4_3_inner_x4_h_1" />
    <limit effort="80" velocity="5" lower="-3.1415927" upper="3.1415927" />
    <axis xyz="0 0 -1" />
  </joint>
  <link name="link_hand_right_1_wrist_yaw_1">
    <visual>
      <origin xyz="0 0 0" rpy="0 0 0" />
      <geometry>
        <mesh filename="./meshes/hand_right_1_wrist_yaw_1.stl" />
      </geometry>
      <material name="link_hand_right_1_wrist_yaw_1_material">
        <color rgba="0.98039216 0.71372549 0.0039215686 1" />
      </material>
    </visual>
    <collision>
      <origin xyz="0 0 0" rpy="0 0 0" />
      <geometry>
        <mesh filename="./meshes/hand_right_1_wrist_yaw_1.stl" />
      </geometry>
    </collision>
    <inertial>
      <mass value="0.060439892" />
      <inertia ixx="0.00012252444" iyy="7.0062832e-05" izz="0.0001120905" ixy="0" ixz="0" iyz="-3.5610326e-05" />
      <origin xyz="0 -0.0434315 -0.02963019" rpy="-0.51883845 -0.51883873 -1.8914113e-06" />
    </inertial>
  </link>
  <joint name="joint_hand_right_1_fastened_7" type="fixed">
    <origin xyz="0.010505773 0.0046774714 -0.0345" rpy="0 0 1.9896753" />
    <parent link="link_hand_right_1_x4_3_inner_x4_h_1" />
    <child link="link_hand_right_1_wrist_yaw_1" />
  </joint>
  <link name="link_hand_right_1_x4_1_pcb_x4_h_1">
    <visual>
      <origin xyz="0 0 0" rpy="0 0 0" />
      <geometry>
        <mesh filename="./meshes/hand_right_1_x4_1_pcb_x4_h_1.stl" />
      </geometry>
      <material name="link_hand_right_1_x4_1_pcb_x4_h_1_material">
        <color rgba="0.97254902 0.52941176 0.0039215686 1" />
      </material>
    </visual>
    <collision>
      <origin xyz="0 0 0" rpy="0 0 0" />
      <geometry>
        <mesh filename="./meshes/hand_right_1_x4_1_pcb_x4_h_1.stl" />
      </geometry>
    </collision>
    <inertial>
      <mass value="0.029564618" />
      <inertia ixx="4.8930802e-06" iyy="6.0010713e-06" izz="9.9964453e-06" ixy="0" ixz="0" iyz="0" />
      <origin xyz="-0.015909902 0.014250747 -0.0067605702" rpy="3.1415927 0 0" />
    </inertial>
  </link>
  <joint name="joint_hand_right_1_fastened_2" type="fixed">
    <origin xyz="0.015909902 -0.0812 -0.068909904" rpy="1.5707963 0 0" />
    <parent link="link_hand_right_1_wrist_yaw_1" />
    <child link="link_hand_right_1_x4_1_pcb_x4_h_1" />
  </joint>
  <link name="link_hand_right_1_x4_1_outer_x4_h_1">
    <visual>
      <origin xyz="0 0 0" rpy="0 0 0" />
      <geometry>
        <mesh filename="./meshes/hand_right_1_x4_1_outer_x4_h_1.stl" />
      </geometry>
      <material name="link_hand_right_1_x4_1_outer_x4_h_1_material">
        <color rgba="0.76862745 0.88627451 0.95294118 1" />
      </material>
    </visual>
    <collision>
      <origin xyz="0 0 0" rpy="0 0 0" />
      <geometry>
        <mesh filename="./meshes/hand_right_1_x4_1_outer_x4_h_1.stl" />
      </geometry>
    </collision>
    <inertial>
      <mass value="0.15533844" />
      <inertia ixx="5.6668323e-05" iyy="5.6668375e-05" izz="8.3408195e-05" ixy="0" ixz="0" iyz="0" />
      <origin xyz="0 0 0.01700001" rpy="1.3941927e-06 0 0" />
    </inertial>
  </link>
  <joint name="joint_hand_right_1_x4_1_fastened_1" type="fixed">
    <origin xyz="-0.015909902 0.015909904 -0.0135" rpy="3.1415927 0 0" />
    <parent link="link_hand_right_1_x4_1_pcb_x4_h_1" />
    <child link="link_hand_right_1_x4_1_outer_x4_h_1" />
  </joint>
  <link name="link_hand_right_1_x4_1_inner_x4_h_1">
    <visual>
      <origin xyz="0 0 0" rpy="0 0 0" />
      <geometry>
        <mesh filename="./meshes/hand_right_1_x4_1_inner_x4_h_1.stl" />
      </geometry>
      <material name="link_hand_right_1_x4_1_inner_x4_h_1_material">
        <color rgba="0.97254902 0.52941176 0.0039215686 1" />
      </material>
    </visual>
    <collision>
      <origin xyz="0 0 0" rpy="0 0 0" />
      <geometry>
        <mesh filename="./meshes/hand_right_1_x4_1_inner_x4_h_1.stl" />
      </geometry>
    </collision>
    <inertial>
      <mass value="0.14964637" />
      <inertia ixx="2.7715788e-05" iyy="2.7715788e-05" izz="2.5745478e-05" ixy="0" ixz="0" iyz="0" />
      <origin xyz="0 0 -0.01725" rpy="3.1415927 0 3.1415927" />
    </inertial>
  </link>
  <joint name="joint_hand_right_1_x4_1_dof_x4" type="revolute">
    <origin xyz="0 0 0" rpy="3.1415927 0 0" />
    <parent link="link_hand_right_1_x4_1_outer_x4_h_1" />
    <child link="link_hand_right_1_x4_1_inner_x4_h_1" />
    <limit effort="80" velocity="5" lower="-2.6179939" upper="0.52359878" />
    <axis xyz="0 0 -1" />
  </joint>
  <link name="link_hand_right_1_twist_mount_1">
    <visual>
      <origin xyz="0 0 0" rpy="0 0 0" />
      <geometry>
        <mesh filename="./meshes/hand_right_1_twist_mount_1.stl" />
      </geometry>
      <material name="link_hand_right_1_twist_mount_1_material">
        <color rgba="0.64705882 0.64705882 0.64705882 1" />
      </material>
    </visual>
    <collision>
      <origin xyz="0 0 0" rpy="0 0 0" />
      <geometry>
        <mesh filename="./meshes/hand_right_1_twist_mount_1.stl" />
      </geometry>
    </collision>
    <inertial>
      <mass value="0.0736663" />
      <inertia ixx="8.1299893e-05" iyy="0.0001454722" izz="0.00013928767" ixy="0" ixz="0" iyz="-9.0812077e-06" />
      <origin xyz="-8.7207636e-05 -0.023388415 -0.035441177" rpy="0 0.00091077936 -3.1411246" />
    </inertial>
  </link>
  <joint name="joint_hand_right_1_fastened_1" type="fixed">
    <origin xyz="-0.0012020773 -0.011437002 -0.0345" rpy="0 0 0" />
    <parent link="link_hand_right_1_x4_1_inner_x4_h_1" />
    <child link="link_hand_right_1_twist_mount_1" />
  </joint>
  <link name="link_hand_right_1_x4_2_pcb_x4_h_1">
    <visual>
      <origin xyz="0 0 0" rpy="0 0 0" />
      <geometry>
        <mesh filename="./meshes/hand_right_1_x4_2_pcb_x4_h_1.stl" />
      </geometry>
      <material name="link_hand_right_1_x4_2_pcb_x4_h_1_material">
        <color rgba="0.97254902 0.52941176 0.0039215686 1" />
      </material>
    </visual>
    <collision>
      <origin xyz="0 0 0" rpy="0 0 0" />
      <geometry>
        <mesh filename="./meshes/hand_right_1_x4_2_pcb_x4_h_1.stl" />
      </geometry>
    </collision>
    <inertial>
      <mass value="0.029564618" />
      <inertia ixx="4.8930802e-06" iyy="6.0010713e-06" izz="9.9964453e-06" ixy="0" ixz="0" iyz="0" />
      <origin xyz="0 -0.0016591571 -0.0067605702" rpy="3.1415927 0 0" />
    </inertial>
  </link>
  <joint name="joint_hand_right_1_fastened_3" type="fixed">
    <origin xyz="0 0.0043 -0.0447" rpy="-1.5707963 0 0" />
    <parent link="link_hand_right_1_twist_mount_1" />
    <child link="link_hand_right_1_x4_2_pcb_x4_h_1" />
  </joint>
  <link name="link_hand_right_1_base_attachment_1">
    <visual>
      <origin xyz="0 0 0" rpy="0 0 0" />
      <geometry>
        <mesh filename="./meshes/hand_right_1_base_attachment_1.stl" />
      </geometry>
      <material name="link_hand_right_1_base_attachment_1_material">
        <color rgba="0.61568627 0.81176471 0.92941176 1" />
      </material>
    </visual>
    <collision>
      <origin xyz="0 0 0" rpy="0 0 0" />
      <geometry>
        <mesh filename="./meshes/hand_right_1_base_attachment_1.stl" />
      </geometry>
    </collision>
    <inertial>
      <mass value="0.011468358" />
      <inertia ixx="6.4460288e-06" iyy="4.2314403e-05" izz="4.8109475e-05" ixy="0" ixz="0" iyz="0" />
      <origin xyz="0.0625 0 -0.0086025856" rpy="3.1415927 0 0" />
    </inertial>
  </link>
  <joint name="joint_hand_right_1_fastened_6" type="fixed">
    <origin xyz="0.0625 -0.0432 -0.0447" rpy="1.5707963 0 3.1415927" />
    <parent link="link_hand_right_1_twist_mount_1" />
    <child link="link_hand_right_1_base_attachment_1" />
  </joint>
  <link name="link_hand_right_1_x4_2_outer_x4_h_1">
    <visual>
      <origin xyz="0 0 0" rpy="0 0 0" />
      <geometry>
        <mesh filename="./meshes/hand_right_1_x4_2_outer_x4_h_1.stl" />
      </geometry>
      <material name="link_hand_right_1_x4_2_outer_x4_h_1_material">
        <color rgba="0.76862745 0.88627451 0.95294118 1" />
      </material>
    </visual>
    <collision>
      <origin xyz="0 0 0" rpy="0 0 0" />
      <geometry>
        <mesh filename="./meshes/hand_right_1_x4_2_outer_x4_h_1.stl" />
      </geometry>
    </collision>
    <inertial>
      <mass value="0.15533844" />
      <inertia ixx="5.6668323e-05" iyy="5.6668375e-05" izz="8.3408195e-05" ixy="0" ixz="0" iyz="0" />
      <origin xyz="0 0 0.01700001" rpy="1.3941927e-06 0 0" />
    </inertial>
  </link>
  <joint name="joint_hand_right_1_x4_2_fastened_1" type="fixed">
    <origin xyz="0 0 -0.0135" rpy="3.1415927 0 0" />
    <parent link="link_hand_right_1_x4_2_pcb_x4_h_1" />
    <child link="link_hand_right_1_x4_2_outer_x4_h_1" />
  </joint>
  <link name="link_hand_right_1_slide_rail_1">
    <visual>
      <origin xyz="0 0 0" rpy="0 0 0" />
      <geometry>
        <mesh filename="./meshes/hand_right_1_slide_rail_1.stl" />
      </geometry>
      <material name="link_hand_right_1_slide_rail_1_material">
        <color rgba="0.61568627 0.81176471 0.92941176 1" />
      </material>
    </visual>
    <collision>
      <origin xyz="0 0 0" rpy="0 0 0" />
      <geometry>
        <mesh filename="./meshes/hand_right_1_slide_rail_1.stl" />
      </geometry>
    </collision>
    <inertial>
      <mass value="0.10830499" />
      <inertia ixx="1.9293716e-06" iyy="0.00020389137" izz="0.00020466548" ixy="0" ixz="0" iyz="0" />
      <origin xyz="0.0625 0 -0.004" rpy="3.1415927 0 0" />
    </inertial>
  </link>
  <joint name="joint_hand_right_1_fastened_10" type="fixed">
    <origin xyz="0.125 0 -0.011" rpy="0 0 3.1415927" />
    <parent link="link_hand_right_1_base_attachment_1" />
    <child link="link_hand_right_1_slide_rail_1" />
  </joint>
  <link name="link_hand_right_1_x4_2_inner_x4_h_1">
    <visual>
      <origin xyz="0 0 0" rpy="0 0 0" />
      <geometry>
        <mesh filename="./meshes/hand_right_1_x4_2_inner_x4_h_1.stl" />
      </geometry>
      <material name="link_hand_right_1_x4_2_inner_x4_h_1_material">
        <color rgba="0.97254902 0.52941176 0.0039215686 1" />
      </material>
    </visual>
    <collision>
      <origin xyz="0 0 0" rpy="0 0 0" />
      <geometry>
        <mesh filename="./meshes/hand_right_1_x4_2_inner_x4_h_1.stl" />
      </geometry>
    </collision>
    <inertial>
      <mass value="0.14964637" />
      <inertia ixx="2.7715788e-05" iyy="2.7715788e-05" izz="2.5745478e-05" ixy="0" ixz="0" iyz="0" />
      <origin xyz="0 0 -0.01725" rpy="3.1415927 0 3.1415927" />
    </inertial>
  </link>
  <joint name="joint_hand_right_1_x4_2_dof_x4" type="revolute">
    <origin xyz="0 0 0" rpy="3.1415927 0 0" />
    <parent link="link_hand_right_1_x4_2_outer_x4_h_1" />
    <child link="link_hand_right_1_x4_2_inner_x4_h_1" />
    <limit effort="80" velocity="5" lower="-3.1415927" upper="3.1415927" />
    <axis xyz="0 0 -1" />
  </joint>
  <link name="link_hand_right_1_slide_2">
    <visual>
      <origin xyz="0 0 0" rpy="0 0 0" />
      <geometry>
        <mesh filename="./meshes/hand_right_1_slide_2.stl" />
      </geometry>
      <material name="link_hand_right_1_slide_2_material">
        <color rgba="0.61568627 0.81176471 0.92941176 1" />
      </material>
    </visual>
    <collision>
      <origin xyz="0 0 0" rpy="0 0 0" />
      <geometry>
        <mesh filename="./meshes/hand_right_1_slide_2.stl" />
      </geometry>
    </collision>
    <inertial>
      <mass value="0.016500413" />
      <inertia ixx="2.973059e-06" iyy="1.0218079e-06" izz="3.926167e-06" ixy="0" ixz="0" iyz="0" />
      <origin xyz="0.002499054 0 -0.023" rpy="3.1415927 0 3.1415927" />
    </inertial>
  </link>
  <joint name="joint_hand_right_1_slider_3" type="prismatic">
    <origin xyz="-0.0125 0 -0.008" rpy="-3.1415927 1.5707963 0" />
    <parent link="link_hand_right_1_slide_rail_1" />
    <child link="link_hand_right_1_slide_2" />
    <limit effort="80" velocity="5" lower="-0.029" upper="0.005" />
    <axis xyz="0 0 -1" />
  </joint>
  <link name="link_hand_right_1_slide_1">
    <visual>
      <origin xyz="0 0 0" rpy="0 0 0" />
      <geometry>
        <mesh filename="./meshes/hand_right_1_slide_1.stl" />
      </geometry>
      <material name="link_hand_right_1_slide_1_material">
        <color rgba="0.61568627 0.81176471 0.92941176 1" />
      </material>
    </visual>
    <collision>
      <origin xyz="0 0 0" rpy="0 0 0" />
      <geometry>
        <mesh filename="./meshes/hand_right_1_slide_1.stl" />
      </geometry>
    </collision>
    <inertial>
      <mass value="0.016500413" />
      <inertia ixx="2.973059e-06" iyy="1.0218079e-06" izz="3.926167e-06" ixy="0" ixz="0" iyz="0" />
      <origin xyz="0.002499054 0 -0.023" rpy="3.1415927 0 3.1415927" />
    </inertial>
  </link>
  <joint name="joint_hand_right_1_slider_1" type="prismatic">
    <origin xyz="0.1375 0 -0.008" rpy="0 1.5707963 0" />
    <parent link="link_hand_right_1_slide_rail_1" />
    <child link="link_hand_right_1_slide_1" />
    <limit effort="80" velocity="5" lower="-0.029" upper="0.005" />
    <axis xyz="0 0 -1" />
    <mimic joint="joint_hand_right_1_slider_3" multiplier="-1" offset="0" />
  </joint>
  <link name="link_hand_right_1_rack_2">
    <visual>
      <origin xyz="0 0 0" rpy="0 0 0" />
      <geometry>
        <mesh filename="./meshes/hand_right_1_rack_2.stl" />
      </geometry>
      <material name="link_hand_right_1_rack_2_material">
        <color rgba="0.64705882 0.64705882 0.64705882 1" />
      </material>
    </visual>
    <collision>
      <origin xyz="0 0 0" rpy="0 0 0" />
      <geometry>
        <mesh filename="./meshes/hand_right_1_rack_2.stl" />
      </geometry>
    </collision>
    <inertial>
      <mass value="0.0061195502" />
      <inertia ixx="1.4114719e-06" iyy="2.8041609e-06" izz="3.1549803e-06" ixy="0" ixz="0" iyz="0" />
      <origin xyz="0.0039811959 0.0049615553 0.0051252105" rpy="-0.086502669 -0.085512537 0.41511208" />
    </inertial>
  </link>
  <joint name="joint_hand_right_1_fastened_8" type="fixed">
    <origin xyz="0.005 0.01 -0.033" rpy="0 -1.5707963 0" />
    <parent link="link_hand_right_1_slide_2" />
    <child link="link_hand_right_1_rack_2" />
  </joint>
  <link name="link_hand_right_1_rack_1">
    <visual>
      <origin xyz="0 0 0" rpy="0 0 0" />
      <geometry>
        <mesh filename="./meshes/hand_right_1_rack_1.stl" />
      </geometry>
      <material name="link_hand_right_1_rack_1_material">
        <color rgba="0.64705882 0.64705882 0.64705882 1" />
      </material>
    </visual>
    <collision>
      <origin xyz="0 0 0" rpy="0 0 0" />
      <geometry>
        <mesh filename="./meshes/hand_right_1_rack_1.stl" />
      </geometry>
    </collision>
    <inertial>
      <mass value="0.0061195502" />
      <inertia ixx="1.4114719e-06" iyy="2.8041609e-06" izz="3.1549803e-06" ixy="0" ixz="0" iyz="0" />
      <origin xyz="0.0039811959 0.02496156 0.0051252105" rpy="-0.086502669 -0.085512537 0.41511208" />
    </inertial>
  </link>
  <joint name="joint_hand_right_1_fastened_12" type="fixed">
    <origin xyz="0.005 -0.01 -0.033" rpy="0 -1.5707963 0" />
    <parent link="link_hand_right_1_slide_1" />
    <child link="link_hand_right_1_rack_1" />
  </joint>
  <link name="link_hand_right_1_gripper_2">
    <visual>
      <origin xyz="0 0 0" rpy="0 0 0" />
      <geometry>
        <mesh filename="./meshes/hand_right_1_gripper_2.stl" />
      </geometry>
      <material name="link_hand_right_1_gripper_2_material">
        <color rgba="0.64705882 0.64705882 0.64705882 1" />
      </material>
    </visual>
    <collision>
      <origin xyz="0 0 0" rpy="0 0 0" />
      <geometry>
        <mesh filename="./meshes/hand_right_1_gripper_2.stl" />
      </geometry>
    </collision>
    <inertial>
      <mass value="0.034294135" />
      <inertia ixx="1.6044041e-05" iyy="2.1207498e-05" izz="8.9235264e-06" ixy="0" ixz="3.1415313e-06" iyz="0" />
      <origin xyz="0.0067900014 0.010305276 -0.024181156" rpy="-1.9607781 0.33467797 -1.7089539" />
    </inertial>
  </link>
  <joint name="joint_hand_right_1_fastened_9" type="fixed">
    <origin xyz="0 -0.020000005 -0.005" rpy="0 0 0" />
    <parent link="link_hand_right_1_rack_2" />
    <child link="link_hand_right_1_gripper_2" />
  </joint>
  <link name="link_hand_right_1_gripper_1">
    <visual>
      <origin xyz="0 0 0" rpy="0 0 0" />
      <geometry>
        <mesh filename="./meshes/hand_right_1_gripper_1.stl" />
      </geometry>
      <material name="link_hand_right_1_gripper_1_material">
        <color rgba="0.64705882 0.64705882 0.64705882 1" />
      </material>
    </visual>
    <collision>
      <origin xyz="0 0 0" rpy="0 0 0" />
      <geometry>
        <mesh filename="./meshes/hand_right_1_gripper_1.stl" />
      </geometry>
    </collision>
    <inertial>
      <mass value="0.034294135" />
      <inertia ixx="1.6044041e-05" iyy="2.1207498e-05" izz="8.9235264e-06" ixy="0" ixz="3.1415313e-06" iyz="0" />
      <origin xyz="0.0067900014 0.010305276 -0.024181156" rpy="-1.9607781 0.33467797 -1.7089539" />
    </inertial>
  </link>
  <joint name="joint_hand_right_1_fastened_14" type="fixed">
    <origin xyz="0 0 -0.005" rpy="0 0 0" />
    <parent link="link_hand_right_1_rack_1" />
    <child link="link_hand_right_1_gripper_1" />
  </joint>
</robot>
