<?xml version='1.0' encoding='utf-8'?>
<robot name="arm">
  <link name="link_right_arm_1_x8_1_outer_1">
    <visual>
      <origin xyz="10 10 10" rpy="1.5707 1.5707 1.5707" />
      <geometry>
        <mesh filename="./meshes/right_arm_1_x8_1_outer_1.stl" />
      </geometry>
      <material name="link_right_arm_1_x8_1_outer_1_material">
        <color rgba="0.91764706 0.91764706 0.91764706 1" />
      </material>
    </visual>
    <collision>
      <origin xyz="0 0 0" rpy="0 0 0" />
      <geometry>
        <mesh filename="./meshes/right_arm_1_x8_1_outer_1.stl" />
      </geometry>
    </collision>
    <inertial>
      <mass value="0.64135588" />
      <inertia ixx="0.0004995997" iyy="0.00049960271" izz="0.00089477222" ixy="0" ixz="0" iyz="0" />
      <origin xyz="0.033978714 -0.024687118 -0.015652571" rpy="-3.1415892 0 0" />
    </inertial>
  </link>
  <link name="link_right_arm_1_x8_1_inner_1">
    <visual>
      <origin xyz="0 0 0" rpy="0 0 0" />
      <geometry>
        <mesh filename="./meshes/right_arm_1_x8_1_inner_1.stl" />
      </geometry>
      <material name="link_right_arm_1_x8_1_inner_1_material">
        <color rgba="0.97254902 0.52941176 0.0039215686 1" />
      </material>
    </visual>
    <collision>
      <origin xyz="0 0 0" rpy="0 0 0" />
      <geometry>
        <mesh filename="./meshes/right_arm_1_x8_1_inner_1.stl" />
      </geometry>
    </collision>
    <inertial>
      <mass value="0.13865861" />
      <inertia ixx="2.7062809e-05" iyy="2.7062809e-05" izz="2.8959079e-05" ixy="0" ixz="0" iyz="0" />
      <origin xyz="0 0 -0.0165" rpy="3.1415927 0 -1.5707963" />
    </inertial>
  </link>
  <joint name="joint_right_arm_1_x8_1_dof_x8" type="revolute">
    <origin xyz="0.033978714 -0.024686981 0" rpy="0 0 0" />
    <parent link="link_right_arm_1_x8_1_outer_1" />
    <child link="link_right_arm_1_x8_1_inner_1" />
    <limit effort="6" velocity="31.4" lower="-2.0943951" upper="2.0943951" />
    <axis xyz="0 0 1" />
  </joint>
  <link name="link_right_arm_1_x8_1_pcb_1">
    <visual>
      <origin xyz="0 0 0" rpy="0 0 0" />
      <geometry>
        <mesh filename="./meshes/right_arm_1_x8_1_pcb_1.stl" />
      </geometry>
      <material name="link_right_arm_1_x8_1_pcb_1_material">
        <color rgba="0.76862745 0.88627451 0.95294118 1" />
      </material>
    </visual>
    <collision>
      <origin xyz="0 0 0" rpy="0 0 0" />
      <geometry>
        <mesh filename="./meshes/right_arm_1_x8_1_pcb_1.stl" />
      </geometry>
    </collision>
    <inertial>
      <mass value="0.048559947" />
      <inertia ixx="1.3682683e-05" iyy="1.6841341e-05" izz="2.9259442e-05" ixy="0" ixz="0" iyz="0" />
      <origin xyz="0 0.0021459929 -0.00625" rpy="3.1415927 0 0" />
    </inertial>
  </link>
  <joint name="joint_right_arm_1_x8_1_fastened_1" type="fixed">
    <origin xyz="0.033978714 -0.024686981 0" rpy="3.1415927 0 0" />
    <parent link="link_right_arm_1_x8_1_outer_1" />
    <child link="link_right_arm_1_x8_1_pcb_1" />
  </joint>
  <link name="link_right_arm_1_shoulder_inner_1">
    <visual>
      <origin xyz="0 0 0" rpy="0 0 0" />
      <geometry>
        <mesh filename="./meshes/right_arm_1_shoulder_inner_1.stl" />
      </geometry>
      <material name="link_right_arm_1_shoulder_inner_1_material">
        <color rgba="0.91764706 0.91764706 0.91764706 1" />
      </material>
    </visual>
    <collision>
      <origin xyz="0 0 0" rpy="0 0 0" />
      <geometry>
        <mesh filename="./meshes/right_arm_1_shoulder_inner_1.stl" />
      </geometry>
    </collision>
    <inertial>
      <mass value="0.089041445" />
      <inertia ixx="0.00018039859" iyy="0.00025314879" izz="0.00015943756" ixy="0" ixz="0" iyz="-3.3536228e-05" />
      <origin xyz="0.0005922134 0.031234355 0.039362496" rpy="1.8814139 -0.0016092833 -1.6004318" />
    </inertial>
  </link>
  <joint name="joint_right_arm_1_fastened_8" type="fixed">
    <origin xyz="0 0.0155 -0.033" rpy="3.1415927 0 0" />
    <parent link="link_right_arm_1_x8_1_inner_1" />
    <child link="link_right_arm_1_shoulder_inner_1" />
  </joint>
  <link name="link_right_arm_1_x8_2_outer_1">
    <visual>
      <origin xyz="0 0 0" rpy="0 0 0" />
      <geometry>
        <mesh filename="./meshes/right_arm_1_x8_2_outer_1.stl" />
      </geometry>
      <material name="link_right_arm_1_x8_2_outer_1_material">
        <color rgba="0.91764706 0.91764706 0.91764706 1" />
      </material>
    </visual>
    <collision>
      <origin xyz="0 0 0" rpy="0 0 0" />
      <geometry>
        <mesh filename="./meshes/right_arm_1_x8_2_outer_1.stl" />
      </geometry>
    </collision>
    <inertial>
      <mass value="0.64135588" />
      <inertia ixx="0.0004995997" iyy="0.00049960271" izz="0.00089477222" ixy="0" ixz="0" iyz="0" />
      <origin xyz="0.012978714 -0.039944512 -0.015652571" rpy="-3.1415892 0 0" />
    </inertial>
  </link>
  <joint name="joint_right_arm_1_fastened_11" type="fixed">
    <origin xyz="-0.012978714 0.0485 0.037055626" rpy="-1.5707963 0 0" />
    <parent link="link_right_arm_1_shoulder_inner_1" />
    <child link="link_right_arm_1_x8_2_outer_1" />
  </joint>
  <link name="link_right_arm_1_x8_2_inner_1">
    <visual>
      <origin xyz="0 0 0" rpy="0 0 0" />
      <geometry>
        <mesh filename="./meshes/right_arm_1_x8_2_inner_1.stl" />
      </geometry>
      <material name="link_right_arm_1_x8_2_inner_1_material">
        <color rgba="0.97254902 0.52941176 0.0039215686 1" />
      </material>
    </visual>
    <collision>
      <origin xyz="0 0 0" rpy="0 0 0" />
      <geometry>
        <mesh filename="./meshes/right_arm_1_x8_2_inner_1.stl" />
      </geometry>
    </collision>
    <inertial>
      <mass value="0.13865861" />
      <inertia ixx="2.7062809e-05" iyy="2.7062809e-05" izz="2.8959079e-05" ixy="0" ixz="0" iyz="0" />
      <origin xyz="0 0 -0.0165" rpy="3.1415927 0 -1.5707963" />
    </inertial>
  </link>
  <joint name="joint_right_arm_1_x8_2_dof_x8" type="revolute">
    <origin xyz="0.012978714 -0.039944374 0" rpy="0 0 0" />
    <parent link="link_right_arm_1_x8_2_outer_1" />
    <child link="link_right_arm_1_x8_2_inner_1" />
    <limit effort="6" velocity="31.4" lower="0" upper="1.9198622" />
    <axis xyz="0 0 1" />
  </joint>
  <link name="link_right_arm_1_x8_2_pcb_1">
    <visual>
      <origin xyz="0 0 0" rpy="0 0 0" />
      <geometry>
        <mesh filename="./meshes/right_arm_1_x8_2_pcb_1.stl" />
      </geometry>
      <material name="link_right_arm_1_x8_2_pcb_1_material">
        <color rgba="0.76862745 0.88627451 0.95294118 1" />
      </material>
    </visual>
    <collision>
      <origin xyz="0 0 0" rpy="0 0 0" />
      <geometry>
        <mesh filename="./meshes/right_arm_1_x8_2_pcb_1.stl" />
      </geometry>
    </collision>
    <inertial>
      <mass value="0.048559947" />
      <inertia ixx="1.3682683e-05" iyy="1.6841341e-05" izz="2.9259442e-05" ixy="0" ixz="0" iyz="0" />
      <origin xyz="0 0.0021459929 -0.00625" rpy="3.1415927 0 0" />
    </inertial>
  </link>
  <joint name="joint_right_arm_1_x8_2_fastened_1" type="fixed">
    <origin xyz="0.012978714 -0.039944374 0" rpy="3.1415927 0 0" />
    <parent link="link_right_arm_1_x8_2_outer_1" />
    <child link="link_right_arm_1_x8_2_pcb_1" />
  </joint>
  <link name="link_right_arm_1_shoulder_nontorso_1">
    <visual>
      <origin xyz="0 0 0" rpy="0 0 0" />
      <geometry>
        <mesh filename="./meshes/right_arm_1_shoulder_nontorso_1.stl" />
      </geometry>
      <material name="link_right_arm_1_shoulder_nontorso_1_material">
        <color rgba="0.91764706 0.91764706 0.91764706 1" />
      </material>
    </visual>
    <collision>
      <origin xyz="0 0 0" rpy="0 0 0" />
      <geometry>
        <mesh filename="./meshes/right_arm_1_shoulder_nontorso_1.stl" />
      </geometry>
    </collision>
    <inertial>
      <mass value="0.058614038" />
      <inertia ixx="8.8565559e-05" iyy="0.00011803845" izz="7.9965413e-05" ixy="0" ixz="0" iyz="1.7871881e-05" />
      <origin xyz="0 -0.0010369772 -0.03299414" rpy="1.1938694 -1.125117e-06 -1.570781" />
    </inertial>
  </link>
  <joint name="joint_right_arm_1_fastened_1" type="fixed">
    <origin xyz="0 0.0155 -0.033" rpy="0 0 0" />
    <parent link="link_right_arm_1_x8_2_inner_1" />
    <child link="link_right_arm_1_shoulder_nontorso_1" />
  </joint>
  <link name="link_right_arm_1_x6_1_outer_1">
    <visual>
      <origin xyz="0 0 0" rpy="0 0 0" />
      <geometry>
        <mesh filename="./meshes/right_arm_1_x6_1_outer_1.stl" />
      </geometry>
      <material name="link_right_arm_1_x6_1_outer_1_material">
        <color rgba="0.97254902 0.52941176 0.0039215686 1" />
      </material>
    </visual>
    <collision>
      <origin xyz="0 0 0" rpy="0 0 0" />
      <geometry>
        <mesh filename="./meshes/right_arm_1_x6_1_outer_1.stl" />
      </geometry>
    </collision>
    <inertial>
      <mass value="0.29628126" />
      <inertia ixx="0.00026587276" iyy="0.00015648465" izz="0.00015648456" ixy="0" ixz="0" iyz="0" />
      <origin xyz="0 0.036 -0.015437886" rpy="-3.1415663 0 -1.5707967" />
    </inertial>
  </link>
  <joint name="joint_right_arm_1_fastened_2" type="fixed">
    <origin xyz="-0.036 0.017 -0.0615" rpy="-1.5707963 -1.5707963 0" />
    <parent link="link_right_arm_1_shoulder_nontorso_1" />
    <child link="link_right_arm_1_x6_1_outer_1" />
  </joint>
  <link name="link_right_arm_1_x6_1_inner_1">
    <visual>
      <origin xyz="0 0 0" rpy="0 0 0" />
      <geometry>
        <mesh filename="./meshes/right_arm_1_x6_1_inner_1.stl" />
      </geometry>
      <material name="link_right_arm_1_x6_1_inner_1_material">
        <color rgba="0.49803922 0.49803922 0.49803922 1" />
      </material>
    </visual>
    <collision>
      <origin xyz="0 0 0" rpy="0 0 0" />
      <geometry>
        <mesh filename="./meshes/right_arm_1_x6_1_inner_1.stl" />
      </geometry>
    </collision>
    <inertial>
      <mass value="0.053731806" />
      <inertia ixx="6.4016694e-06" iyy="7.930353e-06" izz="7.930353e-06" ixy="0" ixz="0" iyz="0" />
      <origin xyz="0 0 -0.01625" rpy="1.5707963 1.5707963 0" />
    </inertial>
  </link>
  <joint name="joint_right_arm_1_x6_1_dof_x6" type="revolute">
    <origin xyz="0 0.036 0" rpy="0 0 0" />
    <parent link="link_right_arm_1_x6_1_outer_1" />
    <child link="link_right_arm_1_x6_1_inner_1" />
    <limit effort="3" velocity="31.4" lower="-1.0471976" upper="3.6651914" />
    <axis xyz="0 0 1" />
  </joint>
  <link name="link_right_arm_1_x6_1_pcb_1">
    <visual>
      <origin xyz="0 0 0" rpy="0 0 0" />
      <geometry>
        <mesh filename="./meshes/right_arm_1_x6_1_pcb_1.stl" />
      </geometry>
      <material name="link_right_arm_1_x6_1_pcb_1_material">
        <color rgba="0.98039216 0.71372549 0.0039215686 1" />
      </material>
    </visual>
    <collision>
      <origin xyz="0 0 0" rpy="0 0 0" />
      <geometry>
        <mesh filename="./meshes/right_arm_1_x6_1_pcb_1.stl" />
      </geometry>
    </collision>
    <inertial>
      <mass value="0.032395494" />
      <inertia ixx="1.3729044e-05" iyy="8.2398782e-06" izz="6.266658e-06" ixy="0" ixz="0" iyz="0" />
      <origin xyz="-0.0024625066 8.0472631e-06 -0.006" rpy="0.003369609 0 1.5707963" />
    </inertial>
  </link>
  <joint name="joint_right_arm_1_x6_1_fastened_1" type="fixed">
    <origin xyz="0 0.036 0" rpy="3.1415927 0 0" />
    <parent link="link_right_arm_1_x6_1_outer_1" />
    <child link="link_right_arm_1_x6_1_pcb_1" />
  </joint>
  <link name="link_right_arm_1_elbow_1">
    <visual>
      <origin xyz="0 0 0" rpy="0 0 0" />
      <geometry>
        <mesh filename="./meshes/right_arm_1_elbow_1.stl" />
      </geometry>
      <material name="link_right_arm_1_elbow_1_material">
        <color rgba="0.97254902 0.52941176 0.0039215686 1" />
      </material>
    </visual>
    <collision>
      <origin xyz="0 0 0" rpy="0 0 0" />
      <geometry>
        <mesh filename="./meshes/right_arm_1_elbow_1.stl" />
      </geometry>
    </collision>
    <inertial>
      <mass value="0.1004773" />
      <inertia ixx="9.0235731e-05" iyy="0.0005118918" izz="0.00045524275" ixy="-1.3625884e-05" ixz="0" iyz="0" />
      <origin xyz="0.035238575 -5.5609449e-05 -0.09478421" rpy="1.6142503 -1.538495 1.5244203" />
    </inertial>
  </link>
  <joint name="joint_right_arm_1_fastened_3" type="fixed">
    <origin xyz="0.00575 0.0099592921 -0.0325" rpy="0 0 -2.0943951" />
    <parent link="link_right_arm_1_x6_1_inner_1" />
    <child link="link_right_arm_1_elbow_1" />
  </joint>
  <link name="link_right_arm_1_x6_2_outer_1">
    <visual>
      <origin xyz="0 0 0" rpy="0 0 0" />
      <geometry>
        <mesh filename="./meshes/right_arm_1_x6_2_outer_1.stl" />
      </geometry>
      <material name="link_right_arm_1_x6_2_outer_1_material">
        <color rgba="0.97254902 0.52941176 0.0039215686 1" />
      </material>
    </visual>
    <collision>
      <origin xyz="0 0 0" rpy="0 0 0" />
      <geometry>
        <mesh filename="./meshes/right_arm_1_x6_2_outer_1.stl" />
      </geometry>
    </collision>
    <inertial>
      <mass value="0.29628126" />
      <inertia ixx="0.00026587276" iyy="0.00015648465" izz="0.00015648456" ixy="0" ixz="0" iyz="0" />
      <origin xyz="-0.031176923 0.018 -0.015437886" rpy="-3.1415663 0 -1.5707967" />
    </inertial>
  </link>
  <joint name="joint_right_arm_1_fastened_4" type="fixed">
    <origin xyz="0.044 0.018 -0.15032309" rpy="-3.1415927 -1.5707963 0" />
    <parent link="link_right_arm_1_elbow_1" />
    <child link="link_right_arm_1_x6_2_outer_1" />
  </joint>
  <link name="link_right_arm_1_x6_2_inner_1">
    <visual>
      <origin xyz="0 0 0" rpy="0 0 0" />
      <geometry>
        <mesh filename="./meshes/right_arm_1_x6_2_inner_1.stl" />
      </geometry>
      <material name="link_right_arm_1_x6_2_inner_1_material">
        <color rgba="0.49803922 0.49803922 0.49803922 1" />
      </material>
    </visual>
    <collision>
      <origin xyz="0 0 0" rpy="0 0 0" />
      <geometry>
        <mesh filename="./meshes/right_arm_1_x6_2_inner_1.stl" />
      </geometry>
    </collision>
    <inertial>
      <mass value="0.053731806" />
      <inertia ixx="6.4016694e-06" iyy="7.930353e-06" izz="7.930353e-06" ixy="0" ixz="0" iyz="0" />
      <origin xyz="0 0 -0.01625" rpy="1.5707963 1.5707963 0" />
    </inertial>
  </link>
  <joint name="joint_right_arm_1_x6_2_dof_x6" type="revolute">
    <origin xyz="-0.031176915 0.018 0" rpy="0 0 0" />
    <parent link="link_right_arm_1_x6_2_outer_1" />
    <child link="link_right_arm_1_x6_2_inner_1" />
    <limit effort="3" velocity="31.4" lower="-1.5707963" upper="1.5707963" />
    <axis xyz="0 0 1" />
  </joint>
  <link name="link_right_arm_1_x6_2_pcb_1">
    <visual>
      <origin xyz="0 0 0" rpy="0 0 0" />
      <geometry>
        <mesh filename="./meshes/right_arm_1_x6_2_pcb_1.stl" />
      </geometry>
      <material name="link_right_arm_1_x6_2_pcb_1_material">
        <color rgba="0.98039216 0.71372549 0.0039215686 1" />
      </material>
    </visual>
    <collision>
      <origin xyz="0 0 0" rpy="0 0 0" />
      <geometry>
        <mesh filename="./meshes/right_arm_1_x6_2_pcb_1.stl" />
      </geometry>
    </collision>
    <inertial>
      <mass value="0.032395494" />
      <inertia ixx="1.3729044e-05" iyy="8.2398782e-06" izz="6.266658e-06" ixy="0" ixz="0" iyz="0" />
      <origin xyz="-0.0024625066 8.0472631e-06 -0.006" rpy="0.003369609 0 1.5707963" />
    </inertial>
  </link>
  <joint name="joint_right_arm_1_x6_2_fastened_1" type="fixed">
    <origin xyz="-0.031176915 0.018 0" rpy="3.1415927 0 0" />
    <parent link="link_right_arm_1_x6_2_outer_1" />
    <child link="link_right_arm_1_x6_2_pcb_1" />
  </joint>
  <link name="link_right_arm_1_forearm_1">
    <visual>
      <origin xyz="0 0 0" rpy="0 0 0" />
      <geometry>
        <mesh filename="./meshes/right_arm_1_forearm_1.stl" />
      </geometry>
      <material name="link_right_arm_1_forearm_1_material">
        <color rgba="0.97254902 0.52941176 0.0039215686 1" />
      </material>
    </visual>
    <collision>
      <origin xyz="0 0 0" rpy="0 0 0" />
      <geometry>
        <mesh filename="./meshes/right_arm_1_forearm_1.stl" />
      </geometry>
    </collision>
    <inertial>
      <mass value="0.048550311" />
      <inertia ixx="9.129897e-05" iyy="3.0999218e-05" izz="7.6788077e-05" ixy="2.7021246e-06" ixz="0" iyz="0" />
      <origin xyz="-0.057265324 0 0.0037405592" rpy="-1.5707235 -0.044692131 -1.570787" />
    </inertial>
  </link>
  <joint name="joint_right_arm_1_fastened_5" type="fixed">
    <origin xyz="0.0115 0 -0.0325" rpy="3.1415927 0 0" />
    <parent link="link_right_arm_1_x6_2_inner_1" />
    <child link="link_right_arm_1_forearm_1" />
  </joint>
  <link name="link_right_arm_1_x4_1_pcb_1">
    <visual>
      <origin xyz="0 0 0" rpy="0 0 0" />
      <geometry>
        <mesh filename="./meshes/right_arm_1_x4_1_pcb_1.stl" />
      </geometry>
      <material name="link_right_arm_1_x4_1_pcb_1_material">
        <color rgba="0.97254902 0.52941176 0.0039215686 1" />
      </material>
    </visual>
    <collision>
      <origin xyz="0 0 0" rpy="0 0 0" />
      <geometry>
        <mesh filename="./meshes/right_arm_1_x4_1_pcb_1.stl" />
      </geometry>
    </collision>
    <inertial>
      <mass value="0.029564618" />
      <inertia ixx="4.8930802e-06" iyy="6.0010713e-06" izz="9.9964453e-06" ixy="0" ixz="0" iyz="0" />
      <origin xyz="-0.015909904 -0.017569059 -0.0067605702" rpy="-3.1414629 0 0" />
    </inertial>
  </link>
  <joint name="joint_right_arm_1_fastened_6" type="fixed">
    <origin xyz="-0.076 0.015909901 0.020909904" rpy="1.5707963 0 1.5707963" />
    <parent link="link_right_arm_1_forearm_1" />
    <child link="link_right_arm_1_x4_1_pcb_1" />
  </joint>
  <link name="link_right_arm_1_x4_1_outer_1">
    <visual>
      <origin xyz="0 0 0" rpy="0 0 0" />
      <geometry>
        <mesh filename="./meshes/right_arm_1_x4_1_outer_1.stl" />
      </geometry>
      <material name="link_right_arm_1_x4_1_outer_1_material">
        <color rgba="0.76862745 0.88627451 0.95294118 1" />
      </material>
    </visual>
    <collision>
      <origin xyz="0 0 0" rpy="0 0 0" />
      <geometry>
        <mesh filename="./meshes/right_arm_1_x4_1_outer_1.stl" />
      </geometry>
    </collision>
    <inertial>
      <mass value="0.15533844" />
      <inertia ixx="5.6668323e-05" iyy="5.6668375e-05" izz="8.3408195e-05" ixy="0" ixz="0" iyz="0" />
      <origin xyz="0 0 0.01700001" rpy="1.3941927e-06 0 0" />
    </inertial>
  </link>
  <joint name="joint_right_arm_1_x4_1_fastened_1" type="fixed">
    <origin xyz="-0.015909904 -0.015909902 -0.0135" rpy="3.1415927 0 0" />
    <parent link="link_right_arm_1_x4_1_pcb_1" />
    <child link="link_right_arm_1_x4_1_outer_1" />
  </joint>
  <link name="link_right_arm_1_x4_1_inner_1">
    <visual>
      <origin xyz="0 0 0" rpy="0 0 0" />
      <geometry>
        <mesh filename="./meshes/right_arm_1_x4_1_inner_1.stl" />
      </geometry>
      <material name="link_right_arm_1_x4_1_inner_1_material">
        <color rgba="0.97254902 0.52941176 0.0039215686 1" />
      </material>
    </visual>
    <collision>
      <origin xyz="0 0 0" rpy="0 0 0" />
      <geometry>
        <mesh filename="./meshes/right_arm_1_x4_1_inner_1.stl" />
      </geometry>
    </collision>
    <inertial>
      <mass value="0.14964637" />
      <inertia ixx="2.7715788e-05" iyy="2.7715788e-05" izz="2.5745478e-05" ixy="0" ixz="0" iyz="0" />
      <origin xyz="0 0 -0.01725" rpy="0 -1.5707963 0" />
    </inertial>
  </link>
  <joint name="joint_right_arm_1_x4_1_dof_x4" type="revolute">
    <origin xyz="0 0 0" rpy="3.1415927 0 0" />
    <parent link="link_right_arm_1_x4_1_outer_1" />
    <child link="link_right_arm_1_x4_1_inner_1" />
    <limit effort="1.5" velocity="31.4" lower="-3.1415927" upper="3.1415927" />
    <axis xyz="0 0 1" />
  </joint>
  <link name="link_right_arm_1_hand_1_wrist_1">
    <visual>
      <origin xyz="0 0 0" rpy="0 0 0" />
      <geometry>
        <mesh filename="./meshes/right_arm_1_hand_1_wrist_1.stl" />
      </geometry>
      <material name="link_right_arm_1_hand_1_wrist_1_material">
        <color rgba="0.61568627 0.81176471 0.92941176 1" />
      </material>
    </visual>
    <collision>
      <origin xyz="0 0 0" rpy="0 0 0" />
      <geometry>
        <mesh filename="./meshes/right_arm_1_hand_1_wrist_1.stl" />
      </geometry>
    </collision>
    <inertial>
      <mass value="0.032979385" />
      <inertia ixx="2.8221289e-05" iyy="3.0251629e-05" izz="2.3787366e-05" ixy="0" ixz="0" iyz="-4.2875289e-06" />
      <origin xyz="0.0099594064 -0.020290934 -0.034446279" rpy="-1.1083768 3.6986568e-06 -1.5707904" />
    </inertial>
  </link>
  <joint name="joint_right_arm_1_fastened_7" type="fixed">
    <origin xyz="-0.0093036954 0.0067595304 -0.0345" rpy="0 0 -0.10471976" />
    <parent link="link_right_arm_1_x4_1_inner_1" />
    <child link="link_right_arm_1_hand_1_wrist_1" />
  </joint>
  <link name="link_right_arm_1_hand_1_x4_1_pcb_1">
    <visual>
      <origin xyz="0 0 0" rpy="0 0 0" />
      <geometry>
        <mesh filename="./meshes/right_arm_1_hand_1_x4_1_pcb_1.stl" />
      </geometry>
      <material name="link_right_arm_1_hand_1_x4_1_pcb_1_material">
        <color rgba="0.97254902 0.52941176 0.0039215686 1" />
      </material>
    </visual>
    <collision>
      <origin xyz="0 0 0" rpy="0 0 0" />
      <geometry>
        <mesh filename="./meshes/right_arm_1_hand_1_x4_1_pcb_1.stl" />
      </geometry>
    </collision>
    <inertial>
      <mass value="0.029564618" />
      <inertia ixx="4.8930802e-06" iyy="6.0010713e-06" izz="9.9964453e-06" ixy="0" ixz="0" iyz="0" />
      <origin xyz="0.015909901 -0.017569061 -0.0067605702" rpy="-3.1414629 0 0" />
    </inertial>
  </link>
  <joint name="joint_right_arm_1_hand_1_fastened_5" type="fixed">
    <origin xyz="-0.0059506118 -0.03375 -0.027590099" rpy="1.5707963 0 0" />
    <parent link="link_right_arm_1_hand_1_wrist_1" />
    <child link="link_right_arm_1_hand_1_x4_1_pcb_1" />
  </joint>
  <link name="link_right_arm_1_hand_1_x4_1_outer_1">
    <visual>
      <origin xyz="0 0 0" rpy="0 0 0" />
      <geometry>
        <mesh filename="./meshes/right_arm_1_hand_1_x4_1_outer_1.stl" />
      </geometry>
      <material name="link_right_arm_1_hand_1_x4_1_outer_1_material">
        <color rgba="0.76862745 0.88627451 0.95294118 1" />
      </material>
    </visual>
    <collision>
      <origin xyz="0 0 0" rpy="0 0 0" />
      <geometry>
        <mesh filename="./meshes/right_arm_1_hand_1_x4_1_outer_1.stl" />
      </geometry>
    </collision>
    <inertial>
      <mass value="0.15533844" />
      <inertia ixx="5.6668323e-05" iyy="5.6668375e-05" izz="8.3408195e-05" ixy="0" ixz="0" iyz="0" />
      <origin xyz="0 0 0.01700001" rpy="1.3941927e-06 0 0" />
    </inertial>
  </link>
  <joint name="joint_right_arm_1_hand_1_x4_1_fastened_1" type="fixed">
    <origin xyz="0.015909902 -0.015909904 -0.0135" rpy="3.1415927 0 0" />
    <parent link="link_right_arm_1_hand_1_x4_1_pcb_1" />
    <child link="link_right_arm_1_hand_1_x4_1_outer_1" />
  </joint>
  <link name="link_right_arm_1_hand_1_x4_1_inner_1">
    <visual>
      <origin xyz="0 0 0" rpy="0 0 0" />
      <geometry>
        <mesh filename="./meshes/right_arm_1_hand_1_x4_1_inner_1.stl" />
      </geometry>
      <material name="link_right_arm_1_hand_1_x4_1_inner_1_material">
        <color rgba="0.97254902 0.52941176 0.0039215686 1" />
      </material>
    </visual>
    <collision>
      <origin xyz="0 0 0" rpy="0 0 0" />
      <geometry>
        <mesh filename="./meshes/right_arm_1_hand_1_x4_1_inner_1.stl" />
      </geometry>
    </collision>
    <inertial>
      <mass value="0.14964637" />
      <inertia ixx="2.7715788e-05" iyy="2.7715788e-05" izz="2.5745478e-05" ixy="0" ixz="0" iyz="0" />
      <origin xyz="0 0 -0.01725" rpy="0 -1.5707963 0" />
    </inertial>
  </link>
  <joint name="joint_right_arm_1_hand_1_x4_1_dof_x4" type="revolute">
    <origin xyz="0 0 0" rpy="3.1415927 0 0" />
    <parent link="link_right_arm_1_hand_1_x4_1_outer_1" />
    <child link="link_right_arm_1_hand_1_x4_1_inner_1" />
    <limit effort="1.5" velocity="31.4" lower="-2.6179939" upper="0.52359878" />
    <axis xyz="0 0 1" />
  </joint>
  <link name="link_right_arm_1_hand_1_mount_1">
    <visual>
      <origin xyz="0 0 0" rpy="0 0 0" />
      <geometry>
        <mesh filename="./meshes/right_arm_1_hand_1_mount_1.stl" />
      </geometry>
      <material name="link_right_arm_1_hand_1_mount_1_material">
        <color rgba="0.61568627 0.81176471 0.92941176 1" />
      </material>
    </visual>
    <collision>
      <origin xyz="0 0 0" rpy="0 0 0" />
      <geometry>
        <mesh filename="./meshes/right_arm_1_hand_1_mount_1.stl" />
      </geometry>
    </collision>
    <inertial>
      <mass value="0.038328354" />
      <inertia ixx="4.6789741e-05" iyy="2.9421361e-05" izz="5.0345465e-05" ixy="0" ixz="0" iyz="-9.1876251e-06" />
      <origin xyz="0.046580714 0.033842878 -0.01141873" rpy="2.7812769 -1.0378886e-06 -2.513274" />
    </inertial>
  </link>
  <joint name="joint_right_arm_1_hand_1_fastened_3" type="fixed">
    <origin xyz="-0.0093036954 0.0067595304 -0.0345" rpy="3.1415927 0 0" />
    <parent link="link_right_arm_1_hand_1_x4_1_inner_1" />
    <child link="link_right_arm_1_hand_1_mount_1" />
  </joint>
  <link name="link_right_arm_1_hand_1_base_1">
    <visual>
      <origin xyz="0 0 0" rpy="0 0 0" />
      <geometry>
        <mesh filename="./meshes/right_arm_1_hand_1_base_1.stl" />
      </geometry>
      <material name="link_right_arm_1_hand_1_base_1_material">
        <color rgba="0.61568627 0.81176471 0.92941176 1" />
      </material>
    </visual>
    <collision>
      <origin xyz="0 0 0" rpy="0 0 0" />
      <geometry>
        <mesh filename="./meshes/right_arm_1_hand_1_base_1.stl" />
      </geometry>
    </collision>
    <inertial>
      <mass value="0.036687122" />
      <inertia ixx="1.6835507e-05" iyy="0.0001653957" izz="0.00015310978" ixy="0" ixz="0" iyz="0" />
      <origin xyz="-0.041999797 0.013073577 0.010964043" rpy="-3.1359843 -2.4974468e-06 0" />
    </inertial>
  </link>
  <joint name="joint_right_arm_1_hand_1_fastened_2" type="fixed">
    <origin xyz="0.053383159 0.090699991 -0.0345" rpy="1.5707963 0 2.1991149" />
    <parent link="link_right_arm_1_hand_1_mount_1" />
    <child link="link_right_arm_1_hand_1_base_1" />
  </joint>
  <link name="link_right_arm_1_hand_1_x4_2_pcb_1">
    <visual>
      <origin xyz="0 0 0" rpy="0 0 0" />
      <geometry>
        <mesh filename="./meshes/right_arm_1_hand_1_x4_2_pcb_1.stl" />
      </geometry>
      <material name="link_right_arm_1_hand_1_x4_2_pcb_1_material">
        <color rgba="0.97254902 0.52941176 0.0039215686 1" />
      </material>
    </visual>
    <collision>
      <origin xyz="0 0 0" rpy="0 0 0" />
      <geometry>
        <mesh filename="./meshes/right_arm_1_hand_1_x4_2_pcb_1.stl" />
      </geometry>
    </collision>
    <inertial>
      <mass value="0.029564618" />
      <inertia ixx="4.8930802e-06" iyy="6.0010713e-06" izz="9.9964453e-06" ixy="0" ixz="0" iyz="0" />
      <origin xyz="0.015909901 -0.017569061 -0.0067605702" rpy="-3.1414629 0 0" />
    </inertial>
  </link>
  <joint name="joint_right_arm_1_hand_1_fastened_7" type="fixed">
    <origin xyz="0.056679101 0.021514055 -0.036409901" rpy="-1.5707963 0 2.1991149" />
    <parent link="link_right_arm_1_hand_1_mount_1" />
    <child link="link_right_arm_1_hand_1_x4_2_pcb_1" />
  </joint>
  <link name="link_right_arm_1_hand_1_slide_rail_1">
    <visual>
      <origin xyz="0 0 0" rpy="0 0 0" />
      <geometry>
        <mesh filename="./meshes/right_arm_1_hand_1_slide_rail_1.stl" />
      </geometry>
      <material name="link_right_arm_1_hand_1_slide_rail_1_material">
        <color rgba="0.23137255 0.38039216 0.70588235 1" />
      </material>
    </visual>
    <collision>
      <origin xyz="0 0 0" rpy="0 0 0" />
      <geometry>
        <mesh filename="./meshes/right_arm_1_hand_1_slide_rail_1.stl" />
      </geometry>
    </collision>
    <inertial>
      <mass value="0.10830499" />
      <inertia ixx="1.9293716e-06" iyy="0.00020466548" izz="0.00020389137" ixy="0" ixz="0" iyz="0" />
      <origin xyz="-0.0625 0 -0.004" rpy="3.1415927 0 0" />
    </inertial>
  </link>
  <joint name="joint_right_arm_1_hand_1_fastened_1" type="fixed">
    <origin xyz="0.0205 0.014 0.021" rpy="3.1415927 0 0" />
    <parent link="link_right_arm_1_hand_1_base_1" />
    <child link="link_right_arm_1_hand_1_slide_rail_1" />
  </joint>
  <link name="link_right_arm_1_hand_1_slide_1">
    <visual>
      <origin xyz="0 0 0" rpy="0 0 0" />
      <geometry>
        <mesh filename="./meshes/right_arm_1_hand_1_slide_1.stl" />
      </geometry>
      <material name="link_right_arm_1_hand_1_slide_1_material">
        <color rgba="0.91764706 0.91764706 0.91764706 1" />
      </material>
    </visual>
    <collision>
      <origin xyz="0 0 0" rpy="0 0 0" />
      <geometry>
        <mesh filename="./meshes/right_arm_1_hand_1_slide_1.stl" />
      </geometry>
    </collision>
    <inertial>
      <mass value="0.016500413" />
      <inertia ixx="1.0218079e-06" iyy="3.926167e-06" izz="2.973059e-06" ixy="0" ixz="0" iyz="0" />
      <origin xyz="-0.002490946 0 -0.023" rpy="0 -1.5707963 0" />
    </inertial>
  </link>
  <joint name="joint_right_arm_1_hand_1_slider_1" type="prismatic">
    <origin xyz="-0.122 0.014 0.029" rpy="3.1415927 1.5707963 0" />
    <parent link="link_right_arm_1_hand_1_base_1" />
    <child link="link_right_arm_1_hand_1_slide_1" />
    <limit effort="80" velocity="5" lower="-0.034" upper="0" />
    <axis xyz="0 0 1" />
  </joint>
  <link name="link_right_arm_1_hand_1_slide_2">
    <visual>
      <origin xyz="0 0 0" rpy="0 0 0" />
      <geometry>
        <mesh filename="./meshes/right_arm_1_hand_1_slide_2.stl" />
      </geometry>
      <material name="link_right_arm_1_hand_1_slide_2_material">
        <color rgba="0.91764706 0.91764706 0.91764706 1" />
      </material>
    </visual>
    <collision>
      <origin xyz="0 0 0" rpy="0 0 0" />
      <geometry>
        <mesh filename="./meshes/right_arm_1_hand_1_slide_2.stl" />
      </geometry>
    </collision>
    <inertial>
      <mass value="0.016500413" />
      <inertia ixx="1.0218079e-06" iyy="3.926167e-06" izz="2.973059e-06" ixy="0" ixz="0" iyz="0" />
      <origin xyz="-0.002490946 0 -0.023" rpy="-3.1415927 1.5707963 0" />
    </inertial>
  </link>
  <joint name="joint_right_arm_1_hand_1_slider_2" type="prismatic">
    <origin xyz="0.038 0.014 0.029" rpy="0 1.5707963 0" />
    <parent link="link_right_arm_1_hand_1_base_1" />
    <child link="link_right_arm_1_hand_1_slide_2" />
    <limit effort="80" velocity="5" lower="-0.034" upper="0" />
    <axis xyz="0 0 1" />
  </joint>
  <link name="link_right_arm_1_hand_1_camera_mount_1">
    <visual>
      <origin xyz="0 0 0" rpy="0 0 0" />
      <geometry>
        <mesh filename="./meshes/right_arm_1_hand_1_camera_mount_1.stl" />
      </geometry>
      <material name="link_right_arm_1_hand_1_camera_mount_1_material">
        <color rgba="0.64705882 0.64705882 0.64705882 1" />
      </material>
    </visual>
    <collision>
      <origin xyz="0 0 0" rpy="0 0 0" />
      <geometry>
        <mesh filename="./meshes/right_arm_1_hand_1_camera_mount_1.stl" />
      </geometry>
    </collision>
    <!-- <inertial>
      <mass value="0.0032944294" />
      <inertia ixx="2.7349677e-06" iyy="2.8207234e-06" izz="0" ixy="0" ixz="0" iyz="0" />
      <origin xyz="0 -0.031404208 -0.015915984" rpy="-2.0704722 -1.5707951 -1.0518706" />
    </inertial> -->
  </link>
  <joint name="joint_right_arm_1_hand_1_fastened_13" type="fixed">
    <origin xyz="-0.042 -0.02123077 0.029" rpy="3.1415927 0 0" />
    <parent link="link_right_arm_1_hand_1_base_1" />
    <child link="link_right_arm_1_hand_1_camera_mount_1" />
  </joint>
  <link name="link_right_arm_1_hand_1_x4_2_outer_1">
    <visual>
      <origin xyz="0 0 0" rpy="0 0 0" />
      <geometry>
        <mesh filename="./meshes/right_arm_1_hand_1_x4_2_outer_1.stl" />
      </geometry>
      <material name="link_right_arm_1_hand_1_x4_2_outer_1_material">
        <color rgba="0.76862745 0.88627451 0.95294118 1" />
      </material>
    </visual>
    <collision>
      <origin xyz="0 0 0" rpy="0 0 0" />
      <geometry>
        <mesh filename="./meshes/right_arm_1_hand_1_x4_2_outer_1.stl" />
      </geometry>
    </collision>
    <inertial>
      <mass value="0.15533844" />
      <inertia ixx="5.6668323e-05" iyy="5.6668375e-05" izz="8.3408195e-05" ixy="0" ixz="0" iyz="0" />
      <origin xyz="0 0 0.01700001" rpy="1.3941927e-06 0 0" />
    </inertial>
  </link>
  <joint name="joint_right_arm_1_hand_1_x4_2_fastened_1" type="fixed">
    <origin xyz="0.015909902 -0.015909904 -0.0135" rpy="3.1415927 0 0" />
    <parent link="link_right_arm_1_hand_1_x4_2_pcb_1" />
    <child link="link_right_arm_1_hand_1_x4_2_outer_1" />
  </joint>
  <link name="link_right_arm_1_hand_1_rack_2">
    <visual>
      <origin xyz="0 0 0" rpy="0 0 0" />
      <geometry>
        <mesh filename="./meshes/right_arm_1_hand_1_rack_2.stl" />
      </geometry>
      <material name="link_right_arm_1_hand_1_rack_2_material">
        <color rgba="0.64705882 0.64705882 0.64705882 1" />
      </material>
    </visual>
    <collision>
      <origin xyz="0 0 0" rpy="0 0 0" />
      <geometry>
        <mesh filename="./meshes/right_arm_1_hand_1_rack_2.stl" />
      </geometry>
    </collision>
    <inertial>
      <mass value="0.017215122" />
      <inertia ixx="9.453196e-06" iyy="9.4019321e-06" izz="1.3471543e-05" ixy="2.3571094e-06" ixz="-1.0187246e-06" iyz="1.2661495e-06" />
      <origin xyz="0.018309291 0.021716039 -0.016174018" rpy="1.677935 -0.81329587 -0.15667974" />
    </inertial>
  </link>
  <joint name="joint_right_arm_1_hand_1_fastened_6" type="fixed">
    <origin xyz="-0.00499 0.01 -0.033" rpy="-3.1415927 -1.5707963 0" />
    <parent link="link_right_arm_1_hand_1_slide_1" />
    <child link="link_right_arm_1_hand_1_rack_2" />
  </joint>
  <link name="link_right_arm_1_hand_1_rack_1">
    <visual>
      <origin xyz="0 0 0" rpy="0 0 0" />
      <geometry>
        <mesh filename="./meshes/right_arm_1_hand_1_rack_1.stl" />
      </geometry>
      <material name="link_right_arm_1_hand_1_rack_1_material">
        <color rgba="0.64705882 0.64705882 0.64705882 1" />
      </material>
    </visual>
    <collision>
      <origin xyz="0 0 0" rpy="0 0 0" />
      <geometry>
        <mesh filename="./meshes/right_arm_1_hand_1_rack_1.stl" />
      </geometry>
    </collision>
    <inertial>
      <mass value="0.017215122" />
      <inertia ixx="9.453196e-06" iyy="9.4019321e-06" izz="1.3471543e-05" ixy="2.3571094e-06" ixz="-1.0187246e-06" iyz="1.2661495e-06" />
      <origin xyz="0.018309291 0.0017160342 -0.016174018" rpy="1.677935 -0.81329587 -0.15667974" />
    </inertial>
  </link>
  <joint name="joint_right_arm_1_hand_1_fastened_12" type="fixed">
    <origin xyz="-0.00499 -0.01 -0.033" rpy="-3.1415927 -1.5707963 0" />
    <parent link="link_right_arm_1_hand_1_slide_2" />
    <child link="link_right_arm_1_hand_1_rack_1" />
  </joint>
  <link name="link_right_arm_1_hand_1_x4_2_inner_1">
    <visual>
      <origin xyz="0 0 0" rpy="0 0 0" />
      <geometry>
        <mesh filename="./meshes/right_arm_1_hand_1_x4_2_inner_1.stl" />
      </geometry>
      <material name="link_right_arm_1_hand_1_x4_2_inner_1_material">
        <color rgba="0.97254902 0.52941176 0.0039215686 1" />
      </material>
    </visual>
    <collision>
      <origin xyz="0 0 0" rpy="0 0 0" />
      <geometry>
        <mesh filename="./meshes/right_arm_1_hand_1_x4_2_inner_1.stl" />
      </geometry>
    </collision>
    <inertial>
      <mass value="0.14964637" />
      <inertia ixx="2.7715788e-05" iyy="2.7715788e-05" izz="2.5745478e-05" ixy="0" ixz="0" iyz="0" />
      <origin xyz="0 0 -0.01725" rpy="0 -1.5707963 0" />
    </inertial>
  </link>
  <joint name="joint_right_arm_1_hand_1_x4_2_dof_x4" type="revolute">
    <origin xyz="0 0 0" rpy="3.1415927 0 0" />
    <parent link="link_right_arm_1_hand_1_x4_2_outer_1" />
    <child link="link_right_arm_1_hand_1_x4_2_inner_1" />
    <limit effort="1.5" velocity="31.4" lower="-3.1415927" upper="3.1415927" />
    <axis xyz="0 0 1" />
  </joint>
  <link name="link_right_arm_1_hand_1_gripper_1">
    <visual>
      <origin xyz="0 0 0" rpy="0 0 0" />
      <geometry>
        <mesh filename="./meshes/right_arm_1_hand_1_gripper_1.stl" />
      </geometry>
      <material name="link_right_arm_1_hand_1_gripper_1_material">
        <color rgba="0.64705882 0.64705882 0.64705882 1" />
      </material>
    </visual>
    <collision>
      <origin xyz="0 0 0" rpy="0 0 0" />
      <geometry>
        <mesh filename="./meshes/right_arm_1_hand_1_gripper_1.stl" />
      </geometry>
    </collision>
    <inertial>
      <mass value="0.038649393" />
      <inertia ixx="2.918512e-05" iyy="1.0356781e-05" izz="3.4975644e-05" ixy="-4.9676729e-06" ixz="0" iyz="0" />
      <origin xyz="0.0067779297 0.010386656 -0.032594366" rpy="1.5601807 1.328022 -3.1350898" />
    </inertial>
  </link>
  <joint name="joint_right_arm_1_hand_1_fastened_10" type="fixed">
    <origin xyz="0 0 -0.0445" rpy="0 0 0" />
    <parent link="link_right_arm_1_hand_1_rack_2" />
    <child link="link_right_arm_1_hand_1_gripper_1" />
  </joint>
  <link name="link_right_arm_1_hand_1_gripper_2">
    <visual>
      <origin xyz="0 0 0" rpy="0 0 0" />
      <geometry>
        <mesh filename="./meshes/right_arm_1_hand_1_gripper_2.stl" />
      </geometry>
      <material name="link_right_arm_1_hand_1_gripper_2_material">
        <color rgba="0.64705882 0.64705882 0.64705882 1" />
      </material>
    </visual>
    <collision>
      <origin xyz="0 0 0" rpy="0 0 0" />
      <geometry>
        <mesh filename="./meshes/right_arm_1_hand_1_gripper_2.stl" />
      </geometry>
    </collision>
    <inertial>
      <mass value="0.038649393" />
      <inertia ixx="2.918512e-05" iyy="1.0356781e-05" izz="3.4975644e-05" ixy="-4.9676729e-06" ixz="0" iyz="0" />
      <origin xyz="0.0067779297 0.010386656 -0.032594366" rpy="1.5601807 1.328022 -3.1350898" />
    </inertial>
  </link>
  <joint name="joint_right_arm_1_hand_1_fastened_11" type="fixed">
    <origin xyz="0 -0.020000005 -0.0445" rpy="0 0 0" />
    <parent link="link_right_arm_1_hand_1_rack_1" />
    <child link="link_right_arm_1_hand_1_gripper_2" />
  </joint>
  <link name="link_right_arm_1_hand_1_spur_gear_(26_teeth)_1">
    <visual>
      <origin xyz="0 0 0" rpy="0 0 0" />
      <geometry>
        <mesh filename="./meshes/right_arm_1_hand_1_spur_gear_(26_teeth)_1.stl" />
      </geometry>
      <material name="link_right_arm_1_hand_1_spur_gear_(26_teeth)_1_material">
        <color rgba="0.61568627 0.81176471 0.92941176 1" />
      </material>
    </visual>
    <collision>
      <origin xyz="0 0 0" rpy="0 0 0" />
      <geometry>
        <mesh filename="./meshes/right_arm_1_hand_1_spur_gear_(26_teeth)_1.stl" />
      </geometry>
    </collision>
    <inertial>
      <mass value="0.0037020243" />
      <inertia ixx="0" iyy="0" izz="0" ixy="0" ixz="0" iyz="0" />
      <origin xyz="0 0.0115 -0.0047841874" rpy="-3.1415927 -1.5707963 0" />
    </inertial>
  </link>
  <joint name="joint_right_arm_1_hand_1_fastened_4" type="fixed">
    <origin xyz="0.010505773 0.0046774714 -0.0345" rpy="0 0 1.9896753" />
    <parent link="link_right_arm_1_hand_1_x4_2_inner_1" />
    <child link="link_right_arm_1_hand_1_spur_gear_(26_teeth)_1" />
  </joint>
</robot>
